Workbook
Name SegmentaciónDeDatos_Eje: #N/A
Name SegmentaciónDeDatos_N_R: #N/A
Name SegmentaciónDeDatos_Situación_Actual: #N/A
Name VALOR_EJE: #REF!
Name VALOR_EJE: #REF!
Name VALOR_EJE: #REF!
Name VALOR_LLANTAS: #REF!
Name VALOR_LLANTAS: #REF!
Name VALOR_LLANTAS: #REF!
Name VALOR_VEHICULOS: #REF!
Name VALOR_VEHICULOS: #REF!
Name VALOR_VEHICULOS: #REF!

Sheet ITN
A1: Seleccione Equipo | D1: EN PROCESO DE CREACIÓN | AJ1: Lista Equipos
A2: A1Q-748 | C2: Tipo: | H2: Código: | AJ2: A1Q-748
AJ3: A2B-678
A4: Rendimiento | C4: Horómetro: | F4: Fecha Inspección:
C5: Kilometraje: | J5: Remanente (NSK) | L5: Presión (PSI) | Q5: RATIOS
A6: Estado Actual | C6: Pos | D6: Codigo | E6: Marca | F6: Medida | G6: Diseño | H6: N-R | J6: Original | K6: Actual | L6: Recomendado | M6: Actual | N6: Diferencia | O6: Tapa Válvula | Q6: #N/A | R6: % Vida Útil | S6: #N/A | T6: Observaciones / Recomendaciones | AE6: Rendimiento
A7: #N/A | C7: 1 | E7: #N/A | F7: #N/A | G7: #N/A | H7: #N/A | J7: #N/A | K7: #N/A | L7: #N/A | M7: #N/A | N7: #N/A | O7: #N/A | Q7: #N/A | R7: #N/A | S7: #N/A | T7: #N/A | U7: #N/A | V7: #N/A | W7: #N/A | X7: #N/A | Y7: #N/A | Z7: #N/A | AA7: #N/A | AB7: #N/A | AC7: #N/A | AE7: #N/A
A8: #N/A | C8: 2 | D8: #N/A | E8: #N/A | F8: #N/A | G8: #N/A | H8: #N/A | J8: #N/A | K8: #N/A | L8: #N/A | M8: #N/A | N8: #N/A | O8: #N/A | Q8: #N/A | R8: #N/A | S8: #N/A | T8: #N/A | U8: #N/A | V8: #N/A | W8: #N/A | X8: #N/A | Y8: #N/A | Z8: #N/A | AA8: #N/A | AB8: #N/A | AC8: #N/A | AE8: #N/A
A9: #N/A | C9: 3 | D9: #N/A | E9: #N/A | F9: #N/A | G9: #N/A | H9: #N/A | J9: #N/A | K9: #N/A | L9: #N/A | M9: #N/A | N9: #N/A | O9: #N/A | Q9: #N/A | R9: #N/A | S9: #N/A | T9: #N/A | U9: #N/A | V9: #N/A | W9: #N/A | X9: #N/A | Y9: #N/A | Z9: #N/A | AA9: #N/A | AB9: #N/A | AC9: #N/A | AE9: #N/A
A10: #N/A | C10: 4 | D10: #N/A | E10: #N/A | F10: #N/A | G10: #N/A | H10: #N/A | J10: #N/A | K10: #N/A | L10: #N/A | M10: #N/A | N10: #N/A | O10: #N/A | Q10: #N/A | R10: #N/A | S10: #N/A | T10: #N/A | U10: #N/A | V10: #N/A | W10: #N/A | X10: #N/A | Y10: #N/A | Z10: #N/A | AA10: #N/A | AB10: #N/A | AC10: #N/A | AE10: #N/A
A11: #N/A | C11: 5 | D11: #N/A | E11: #N/A | F11: #N/A | G11: #N/A | H11: #N/A | J11: #N/A | K11: #N/A | L11: #N/A | M11: #N/A | N11: #N/A | O11: #N/A | Q11: #N/A | R11: #N/A | S11: #N/A | T11: #N/A | U11: #N/A | V11: #N/A | W11: #N/A | X11: #N/A | Y11: #N/A | Z11: #N/A | AA11: #N/A | AB11: #N/A | AC11: #N/A | AE11: #N/A
A12: #N/A | C12: 6 | D12: #N/A | E12: #N/A | F12: #N/A | G12: #N/A | H12: #N/A | J12: #N/A | K12: #N/A | L12: #N/A | M12: #N/A | N12: #N/A | O12: #N/A | Q12: #N/A | R12: #N/A | S12: #N/A | T12: #N/A | U12: #N/A | V12: #N/A | W12: #N/A | X12: #N/A | Y12: #N/A | Z12: #N/A | AA12: #N/A | AB12: #N/A | AC12: #N/A | AE12: #N/A
V14: 1 | AA14: 2
V15: #N/A | AA15: #N/A
V16: 3 | AA16: 4
V18: 5 | AA18: 6

Sheet BASE_DATOS
O3: 23 | P3: 24 | Q3: 25 | R3: 26 | S3: 27 | T3: 28 | U3: 29 | V3: 30 | W3: 31 | X3: 32 | Y3: 33 | Z3: 37 | AC3: 38 | AD3: 39 | AE3: 40 | AF3: 41 | AG3: 42 | AH3: 43 | AI3: 44 | AJ3: 45 | AK3: 46 | AL3: 47 | AM3: 48 | AN3: 49 | AO3: 50 | AP3: 51 | AQ3: 52 | AR3: 53
A4: DATOS DE LA UNIDAD | E4: DATOS DEL NEUMÁTICO | O4: INSTALACIÓN | R4: INSPECCIÓN / DESINSTALACIÓN | AA4: RATIOS | AI4: RENDIMIENTO EN HORAS | AN4: RENDIMIENTO EN KILÓMETROS | AS4: 54 | AW4: 64 | AX4: 65
A5: Código_U | B5: Placa_U | C5: Tipo_U | D5: Eje | E5: Código_N | F5: Marca_N | G5: Medida_N | H5: Diseño_N | I5: Diseño | J5: N-R | K5: NSK Original | L5: PSI Rec. | M5: Precio US$ | N5: Proveedor | O5: Fecha | P5: Hr. | Q5: Km. | R5: Pos. | S5: Fecha2 | T5: Hr. Actual | U5: Km. Actual | V5: Ext. | W5: Cen. | X5: Int. | Y5: NSK | Z5: Tapa Válvula | AA5: Des. mm | AB5: NSK Reen | AC5: NSK Form. | AD5: % Max Des. | AE5: % Des | AF5: % Vida Útil | AG5: Horas Acumuladas | AH5: Kilómetros Acumulados | AI5: Horas Rodadas | AJ5: US$/Hr | AK5: Hrs/mm | AL5: Horas Proy. | AM5: US$/Hr Proy. | AN5: Kilómetros Rodados | AO5: US$/ Km | AP5: Kms/ mm | AQ5: Kilómetros Proy. | AR5: US$/Km Proy. | AS5: Situación Actual | AT5: Daños | AU5: Desgaste Irregular | AV5: Rotación | AW5: Observaciones Daños | AX5: Observaciones Desgaste Irregular | AY5: Reporte NSK
A6: TC-100 | B6: F8U-901 | C6: Tracto | D6: Direccional | F6: Goodyear | G6: 295/80R22.5 | H6: =IF(BASE_DATOS[[#This Row],[N-R]]="N",BASE_DATOS[[#This Row],[Diseño]],"Reencauche") -> KMAX S | I6: KMAX S | J6: N | K6: 15.8 | L6: 100 | R6: 1 | S6: 45385 | V6: 12 | W6: 13 | X6: 12 | Y6: =IFERROR(MIN(V6:X6),"") -> 12 | Z6: st | AA6: =IFERROR(BASE_DATOS[[#This Row],[NSK Original]]-BASE_DATOS[[#This Row],[NSK]]," ") -> 3.8 | AB6: ='NSK-TRACTO'!$A$2 -> 6 | AC6: =IF(BASE_DATOS[[#This Row],[NSK]]>=BASE_DATOS[[#This Row],[NSK Reen]],BASE_DATOS[[#This Row],[NSK Reen]],BASE_DATOS[[#This Row],[NSK]]) -> 6 | AD6: =IFERROR(100%-(BASE_DATOS[[#This Row],[NSK Reen]]/BASE_DATOS[[#This Row],[NSK Original]]),"") -> 0.62025316 | AE6: =IFERROR(100%-BASE_DATOS[[#This Row],[NSK]]/BASE_DATOS[[#This Row],[NSK Original]],"") -> 0.24050633 | AF6: =IFERROR(BASE_DATOS[[#This Row],[% Max Des.]]-BASE_DATOS[[#This Row],[% Des]],"") -> 0.37974684 | AI6: =IF(OR(BASE_DATOS[[#This Row],[Hr.]]="",BASE_DATOS[[#This Row],[Hr. Actual]]=""),"",BASE_DATOS[[#This Row],[Hr. Actual]]-BASE_DATOS[[#This Row],[Hr.]]+BASE_DATOS[[#This Row],[Horas Acumuladas]]) | AJ6: =IFERROR(BASE_DATOS[[#This Row],[Precio US$]]/BASE_DATOS[[#This Row],[Horas Rodadas]],"") | AK6: =IFERROR(BASE_DATOS[[#This Row],[Horas Rodadas]]/(BASE_DATOS[[#This Row],[NSK Original]]-BASE_DATOS[[#This Row],[NSK]]),"") | AL6: =IF(BASE_DATOS[[#This Row],[Situación Actual]]="RETIRADO","",IF(BASE_DATOS[[#This Row],[Situación Actual]]="RODANDO",IFERROR(BASE_DATOS[[#This Row],[Hrs/mm]]*(BASE_DATOS[[#This Row],[NSK]]-BASE_DATOS[[#This Row],[NSK Form.]])+BASE_DATOS[[#This Row],[Horas Rodadas]],""))) | AM6: =IFERROR(BASE_DATOS[[#This Row],[Precio US$]]/BASE_DATOS[[#This Row],[Horas Proy.]],"") | AN6: =IF(OR(BASE_DATOS[[#This Row],[Km.]]="",BASE_DATOS[[#This Row],[Km. Actual]]=""),"",BASE_DATOS[[#This Row],[Km. Actual]]-BASE_DATOS[[#This Row],[Km.]]+BASE_DATOS[[#This Row],[Kilómetros Acumulados]]) | AO6: =IFERROR(BASE_DATOS[[#This Row],[Precio US$]]/BASE_DATOS[[#This Row],[Kilómetros Rodados]],"") | AP6: =IFERROR(BASE_DATOS[[#This Row],[Kilómetros Rodados]]/(BASE_DATOS[[#This Row],[NSK Original]]-BASE_DATOS[[#This Row],[NSK]]),"") | AQ6: =IF(BASE_DATOS[[#This Row],[Situación Actual]]="RETIRADO","",IF(BASE_DATOS[[#This Row],[Situación Actual]]="RODANDO",IFERROR(BASE_DATOS[[#This Row],[Kms/ mm]]*(BASE_DATOS[[#This Row],[NSK]]-BASE_DATOS[[#This Row],[NSK Form.]])+BASE_DATOS[[#This Row],[Kilómetros Rodados]],""))) | AR6: =IFERROR(BASE_DATOS[[#This Row],[Precio US$]]/BASE_DATOS[[#This Row],[Kilómetros Proy.]],"") | AS6: Rodando | AY6: =CONCATENATE(BASE_DATOS[[#This Row],[Código_U]]&BASE_DATOS[[#This Row],[Pos.]]&BASE_DATOS[[#This Row],[Situación Actual]]) -> TC-1001Rodando
A7: TC-100 | B7: F8U-901 | C7: Tracto | D7: Direccional | F7: Goodyear | G7: 295/80R22.5 | H7: =IF(BASE_DATOS[[#This Row],[N-R]]="N",BASE_DATOS[[#This Row],[Diseño]],"Reencauche") -> KMAX S | I7: KMAX S | J7: N | K7: 15.8 | L7: 100 | R7: 2 | S7: 45385 | V7: 13 | W7: 14 | X7: 13 | Y7: =IFERROR(MIN(V7:X7),"") -> 13 | Z7: st | AA7: =IFERROR(BASE_DATOS[[#This Row],[NSK Original]]-BASE_DATOS[[#This Row],[NSK]]," ") -> 2.8 | AB7: ='NSK-TRACTO'!$A$2 -> 6 | AC7: =IF(BASE_DATOS[[#This Row],[NSK]]>=BASE_DATOS[[#This Row],[NSK Reen]],BASE_DATOS[[#This Row],[NSK Reen]],BASE_DATOS[[#This Row],[NSK]]) -> 6 | AD7: =IFERROR(100%-(BASE_DATOS[[#This Row],[NSK Reen]]/BASE_DATOS[[#This Row],[NSK Original]]),"") -> 0.62025316 | AE7: =IFERROR(100%-BASE_DATOS[[#This Row],[NSK]]/BASE_DATOS[[#This Row],[NSK Original]],"") -> 0.17721519 | AF7: =IFERROR(BASE_DATOS[[#This Row],[% Max Des.]]-BASE_DATOS[[#This Row],[% Des]],"") -> 0.44303797 | AI7: =IF(OR(BASE_DATOS[[#This Row],[Hr.]]="",BASE_DATOS[[#This Row],[Hr. Actual]]=""),"",BASE_DATOS[[#This Row],[Hr. Actual]]-BASE_DATOS[[#This Row],[Hr.]]+BASE_DATOS[[#This Row],[Horas Acumuladas]]) | AJ7: =IFERROR(BASE_DATOS[[#This Row],[Precio US$]]/BASE_DATOS[[#This Row],[Horas Rodadas]],"") | AK7: =IFERROR(BASE_DATOS[[#This Row],[Horas Rodadas]]/(BASE_DATOS[[#This Row],[NSK Original]]-BASE_DATOS[[#This Row],[NSK]]),"") | AL7: =IF(BASE_DATOS[[#This Row],[Situación Actual]]="RETIRADO","",IF(BASE_DATOS[[#This Row],[Situación Actual]]="RODANDO",IFERROR(BASE_DATOS[[#This Row],[Hrs/mm]]*(BASE_DATOS[[#This Row],[NSK]]-BASE_DATOS[[#This Row],[NSK Form.]])+BASE_DATOS[[#This Row],[Horas Rodadas]],""))) | AM7: =IFERROR(BASE_DATOS[[#This Row],[Precio US$]]/BASE_DATOS[[#This Row],[Horas Proy.]],"") | AN7: =IF(OR(BASE_DATOS[[#This Row],[Km.]]="",BASE_DATOS[[#This Row],[Km. Actual]]=""),"",BASE_DATOS[[#This Row],[Km. Actual]]-BASE_DATOS[[#This Row],[Km.]]+BASE_DATOS[[#This Row],[Kilómetros Acumulados]]) | AO7: =IFERROR(BASE_DATOS[[#This Row],[Precio US$]]/BASE_DATOS[[#This Row],[Kilómetros Rodados]],"") | AP7: =IFERROR(BASE_DATOS[[#This Row],[Kilómetros Rodados]]/(BASE_DATOS[[#This Row],[NSK Original]]-BASE_DATOS[[#This Row],[NSK]]),"") | AQ7: =IF(BASE_DATOS[[#This Row],[Situación Actual]]="RETIRADO","",IF(BASE_DATOS[[#This Row],[Situación Actual]]="RODANDO",IFERROR(BASE_DATOS[[#This Row],[Kms/ mm]]*(BASE_DATOS[[#This Row],[NSK]]-BASE_DATOS[[#This Row],[NSK Form.]])+BASE_DATOS[[#This Row],[Kilómetros Rodados]],""))) | AR7: =IFERROR(BASE_DATOS[[#This Row],[Precio US$]]/BASE_DATOS[[#This Row],[Kilómetros Proy.]],"") | AS7: Rodando | AY7: =CONCATENATE(BASE_DATOS[[#This Row],[Código_U]]&BASE_DATOS[[#This Row],[Pos.]]&BASE_DATOS[[#This Row],[Situación Actual]]) -> TC-1002Rodando
A8: TC-100 | B8: F8U-901 | C8: Tracto | D8: Tracción | F8: Continental | G8: 295/80R22.5 | H8: =IF(BASE_DATOS[[#This Row],[N-R]]="N",BASE_DATOS[[#This Row],[Diseño]],"Reencauche") -> Reencauche | I8: MDE | J8: 1R | K8: 22 | L8: 110 | R8: 3 | S8: 45385 | V8: 20 | X8: 20 | Y8: =IFERROR(MIN(V8:X8),"") -> 20 | Z8: st | AA8: =IFERROR(BASE_DATOS[[#This Row],[NSK Original]]-BASE_DATOS[[#This Row],[NSK]]," ") -> 2 | AB8: ='NSK-TRACTO'!$A$2 -> 6 | AC8: =IF(BASE_DATOS[[#This Row],[NSK]]>=BASE_DATOS[[#This Row],[NSK Reen]],BASE_DATOS[[#This Row],[NSK Reen]],BASE_DATOS[[#This Row],[NSK]]) -> 6 | AD8: =IFERROR(100%-(BASE_DATOS[[#This Row],[NSK Reen]]/BASE_DATOS[[#This Row],[NSK Original]]),"") -> 0.72727273 | AE8: =IFERROR(100%-BASE_DATOS[[#This Row],[NSK]]/BASE_DATOS[[#This Row],[NSK Original]],"") -> 0.090909091 | AF8: =IFERROR(BASE_DATOS[[#This Row],[% Max Des.]]-BASE_DATOS[[#This Row],[% Des]],"") -> 0.63636364 | AI8: =IF(OR(BASE_DATOS[[#This Row],[Hr.]]="",BASE_DATOS[[#This Row],[Hr. Actual]]=""),"",BASE_DATOS[[#This Row],[Hr. Actual]]-BASE_DATOS[[#This Row],[Hr.]]+BASE_DATOS[[#This Row],[Horas Acumuladas]]) | AJ8: =IFERROR(BASE_DATOS[[#This Row],[Precio US$]]/BASE_DATOS[[#This Row],[Horas Rodadas]],"") | AK8: =IFERROR(BASE_DATOS[[#This Row],[Horas Rodadas]]/(BASE_DATOS[[#This Row],[NSK Original]]-BASE_DATOS[[#This Row],[NSK]]),"") | AL8: =IF(BASE_DATOS[[#This Row],[Situación Actual]]="RETIRADO","",IF(BASE_DATOS[[#This Row],[Situación Actual]]="RODANDO",IFERROR(BASE_DATOS[[#This Row],[Hrs/mm]]*(BASE_DATOS[[#This Row],[NSK]]-BASE_DATOS[[#This Row],[NSK Form.]])+BASE_DATOS[[#This Row],[Horas Rodadas]],""))) | AM8: =IFERROR(BASE_DATOS[[#This Row],[Precio US$]]/BASE_DATOS[[#This Row],[Horas Proy.]],"") | AN8: =IF(OR(BASE_DATOS[[#This Row],[Km.]]="",BASE_DATOS[[#This Row],[Km. Actual]]=""),"",BASE_DATOS[[#This Row],[Km. Actual]]-BASE_DATOS[[#This Row],[Km.]]+BASE_DATOS[[#This Row],[Kilómetros Acumulados]]) | AO8: =IFERROR(BASE_DATOS[[#This Row],[Precio US$]]/BASE_DATOS[[#This Row],[Kilómetros Rodados]],"") | AP8: =IFERROR(BASE_DATOS[[#This Row],[Kilómetros Rodados]]/(BASE_DATOS[[#This Row],[NSK Original]]-BASE_DATOS[[#This Row],[NSK]]),"") | AQ8: =IF(BASE_DATOS[[#This Row],[Situación Actual]]="RETIRADO","",IF(BASE_DATOS[[#This Row],[Situación Actual]]="RODANDO",IFERROR(BASE_DATOS[[#This Row],[Kms/ mm]]*(BASE_DATOS[[#This Row],[NSK]]-BASE_DATOS[[#This Row],[NSK Form.]])+BASE_DATOS[[#This Row],[Kilómetros Rodados]],""))) | AR8: =IFERROR(BASE_DATOS[[#This Row],[Precio US$]]/BASE_DATOS[[#This Row],[Kilómetros Proy.]],"") | AS8: Rodando | AY8: =CONCATENATE(BASE_DATOS[[#This Row],[Código_U]]&BASE_DATOS[[#This Row],[Pos.]]&BASE_DATOS[[#This Row],[Situación Actual]]) -> TC-1003Rodando
A9: TC-100 | B9: F8U-901 | C9: Tracto | D9: Tracción | F9: Continental | G9: 295/80R22.5 | H9: =IF(BASE_DATOS[[#This Row],[N-R]]="N",BASE_DATOS[[#This Row],[Diseño]],"Reencauche") -> Reencauche | I9: MDE | J9: 1R | K9: 22 | L9: 110 | R9: 4 | S9: 45385 | V9: 20 | X9: 20 | Y9: =IFERROR(MIN(V9:X9),"") -> 20 | Z9: tm | AA9: =IFERROR(BASE_DATOS[[#This Row],[NSK Original]]-BASE_DATOS[[#This Row],[NSK]]," ") -> 2 | AB9: ='NSK-TRACTO'!$A$2 -> 6 | AC9: =IF(BASE_DATOS[[#This Row],[NSK]]>=BASE_DATOS[[#This Row],[NSK Reen]],BASE_DATOS[[#This Row],[NSK Reen]],BASE_DATOS[[#This Row],[NSK]]) -> 6 | AD9: =IFERROR(100%-(BASE_DATOS[[#This Row],[NSK Reen]]/BASE_DATOS[[#This Row],[NSK Original]]),"") -> 0.72727273 | AE9: =IFERROR(100%-BASE_DATOS[[#This Row],[NSK]]/BASE_DATOS[[#This Row],[NSK Original]],"") -> 0.090909091 | AF9: =IFERROR(BASE_DATOS[[#This Row],[% Max Des.]]-BASE_DATOS[[#This Row],[% Des]],"") -> 0.63636364 | AI9: =IF(OR(BASE_DATOS[[#This Row],[Hr.]]="",BASE_DATOS[[#This Row],[Hr. Actual]]=""),"",BASE_DATOS[[#This Row],[Hr. Actual]]-BASE_DATOS[[#This Row],[Hr.]]+BASE_DATOS[[#This Row],[Horas Acumuladas]]) | AJ9: =IFERROR(BASE_DATOS[[#This Row],[Precio US$]]/BASE_DATOS[[#This Row],[Horas Rodadas]],"") | AK9: =IFERROR(BASE_DATOS[[#This Row],[Horas Rodadas]]/(BASE_DATOS[[#This Row],[NSK Original]]-BASE_DATOS[[#This Row],[NSK]]),"") | AL9: =IF(BASE_DATOS[[#This Row],[Situación Actual]]="RETIRADO","",IF(BASE_DATOS[[#This Row],[Situación Actual]]="RODANDO",IFERROR(BASE_DATOS[[#This Row],[Hrs/mm]]*(BASE_DATOS[[#This Row],[NSK]]-BASE_DATOS[[#This Row],[NSK Form.]])+BASE_DATOS[[#This Row],[Horas Rodadas]],""))) | AM9: =IFERROR(BASE_DATOS[[#This Row],[Precio US$]]/BASE_DATOS[[#This Row],[Horas Proy.]],"") | AN9: =IF(OR(BASE_DATOS[[#This Row],[Km.]]="",BASE_DATOS[[#This Row],[Km. Actual]]=""),"",BASE_DATOS[[#This Row],[Km. Actual]]-BASE_DATOS[[#This Row],[Km.]]+BASE_DATOS[[#This Row],[Kilómetros Acumulados]]) | AO9: =IFERROR(BASE_DATOS[[#This Row],[Precio US$]]/BASE_DATOS[[#This Row],[Kilómetros Rodados]],"") | AP9: =IFERROR(BASE_DATOS[[#This Row],[Kilómetros Rodados]]/(BASE_DATOS[[#This Row],[NSK Original]]-BASE_DATOS[[#This Row],[NSK]]),"") | AQ9: =IF(BASE_DATOS[[#This Row],[Situación Actual]]="RETIRADO","",IF(BASE_DATOS[[#This Row],[Situación Actual]]="RODANDO",IFERROR(BASE_DATOS[[#This Row],[Kms/ mm]]*(BASE_DATOS[[#This Row],[NSK]]-BASE_DATOS[[#This Row],[NSK Form.]])+BASE_DATOS[[#This Row],[Kilómetros Rodados]],""))) | AR9: =IFERROR(BASE_DATOS[[#This Row],[Precio US$]]/BASE_DATOS[[#This Row],[Kilómetros Proy.]],"") | AS9: Rodando | AY9: =CONCATENATE(BASE_DATOS[[#This Row],[Código_U]]&BASE_DATOS[[#This Row],[Pos.]]&BASE_DATOS[[#This Row],[Situación Actual]]) -> TC-1004Rodando
A10: TC-100 | B10: F8U-901 | C10: Tracto | D10: Tracción | F10: Continental | G10: 295/80R22.5 | H10: =IF(BASE_DATOS[[#This Row],[N-R]]="N",BASE_DATOS[[#This Row],[Diseño]],"Reencauche") -> Reencauche | I10: MDE | J10: 1R | K10: 22 | L10: 110 | R10: 5 | S10: 45385 | V10: 20 | X10: 20 | Y10: =IFERROR(MIN(V10:X10),"") -> 20 | Z10: st | AA10: =IFERROR(BASE_DATOS[[#This Row],[NSK Original]]-BASE_DATOS[[#This Row],[NSK]]," ") -> 2 | AB10: ='NSK-TRACTO'!$A$2 -> 6 | AC10: =IF(BASE_DATOS[[#This Row],[NSK]]>=BASE_DATOS[[#This Row],[NSK Reen]],BASE_DATOS[[#This Row],[NSK Reen]],BASE_DATOS[[#This Row],[NSK]]) -> 6 | AD10: =IFERROR(100%-(BASE_DATOS[[#This Row],[NSK Reen]]/BASE_DATOS[[#This Row],[NSK Original]]),"") -> 0.72727273 | AE10: =IFERROR(100%-BASE_DATOS[[#This Row],[NSK]]/BASE_DATOS[[#This Row],[NSK Original]],"") -> 0.090909091 | AF10: =IFERROR(BASE_DATOS[[#This Row],[% Max Des.]]-BASE_DATOS[[#This Row],[% Des]],"") -> 0.63636364 | AI10: =IF(OR(BASE_DATOS[[#This Row],[Hr.]]="",BASE_DATOS[[#This Row],[Hr. Actual]]=""),"",BASE_DATOS[[#This Row],[Hr. Actual]]-BASE_DATOS[[#This Row],[Hr.]]+BASE_DATOS[[#This Row],[Horas Acumuladas]]) | AJ10: =IFERROR(BASE_DATOS[[#This Row],[Precio US$]]/BASE_DATOS[[#This Row],[Horas Rodadas]],"") | AK10: =IFERROR(BASE_DATOS[[#This Row],[Horas Rodadas]]/(BASE_DATOS[[#This Row],[NSK Original]]-BASE_DATOS[[#This Row],[NSK]]),"") | AL10: =IF(BASE_DATOS[[#This Row],[Situación Actual]]="RETIRADO","",IF(BASE_DATOS[[#This Row],[Situación Actual]]="RODANDO",IFERROR(BASE_DATOS[[#This Row],[Hrs/mm]]*(BASE_DATOS[[#This Row],[NSK]]-BASE_DATOS[[#This Row],[NSK Form.]])+BASE_DATOS[[#This Row],[Horas Rodadas]],""))) | AM10: =IFERROR(BASE_DATOS[[#This Row],[Precio US$]]/BASE_DATOS[[#This Row],[Horas Proy.]],"") | AN10: =IF(OR(BASE_DATOS[[#This Row],[Km.]]="",BASE_DATOS[[#This Row],[Km. Actual]]=""),"",BASE_DATOS[[#This Row],[Km. Actual]]-BASE_DATOS[[#This Row],[Km.]]+BASE_DATOS[[#This Row],[Kilómetros Acumulados]]) | AO10: =IFERROR(BASE_DATOS[[#This Row],[Precio US$]]/BASE_DATOS[[#This Row],[Kilómetros Rodados]],"") | AP10: =IFERROR(BASE_DATOS[[#This Row],[Kilómetros Rodados]]/(BASE_DATOS[[#This Row],[NSK Original]]-BASE_DATOS[[#This Row],[NSK]]),"") | AQ10: =IF(BASE_DATOS[[#This Row],[Situación Actual]]="RETIRADO","",IF(BASE_DATOS[[#This Row],[Situación Actual]]="RODANDO",IFERROR(BASE_DATOS[[#This Row],[Kms/ mm]]*(BASE_DATOS[[#This Row],[NSK]]-BASE_DATOS[[#This Row],[NSK Form.]])+BASE_DATOS[[#This Row],[Kilómetros Rodados]],""))) | AR10: =IFERROR(BASE_DATOS[[#This Row],[Precio US$]]/BASE_DATOS[[#This Row],[Kilómetros Proy.]],"") | AS10: Rodando | AY10: =CONCATENATE(BASE_DATOS[[#This Row],[Código_U]]&BASE_DATOS[[#This Row],[Pos.]]&BASE_DATOS[[#This Row],[Situación Actual]]) -> TC-1005Rodando
A11: TC-100 | B11: F8U-901 | C11: Tracto | D11: Tracción | F11: Continental | G11: 295/80R22.5 | H11: =IF(BASE_DATOS[[#This Row],[N-R]]="N",BASE_DATOS[[#This Row],[Diseño]],"Reencauche") -> Reencauche | I11: MDE | J11: 1R | K11: 22 | L11: 110 | R11: 6 | S11: 45385 | V11: 20 | X11: 20 | Y11: =IFERROR(MIN(V11:X11),"") -> 20 | Z11: st | AA11: =IFERROR(BASE_DATOS[[#This Row],[NSK Original]]-BASE_DATOS[[#This Row],[NSK]]," ") -> 2 | AB11: ='NSK-TRACTO'!$A$2 -> 6 | AC11: =IF(BASE_DATOS[[#This Row],[NSK]]>=BASE_DATOS[[#This Row],[NSK Reen]],BASE_DATOS[[#This Row],[NSK Reen]],BASE_DATOS[[#This Row],[NSK]]) -> 6 | AD11: =IFERROR(100%-(BASE_DATOS[[#This Row],[NSK Reen]]/BASE_DATOS[[#This Row],[NSK Original]]),"") -> 0.72727273 | AE11: =IFERROR(100%-BASE_DATOS[[#This Row],[NSK]]/BASE_DATOS[[#This Row],[NSK Original]],"") -> 0.090909091 | AF11: =IFERROR(BASE_DATOS[[#This Row],[% Max Des.]]-BASE_DATOS[[#This Row],[% Des]],"") -> 0.63636364 | AI11: =IF(OR(BASE_DATOS[[#This Row],[Hr.]]="",BASE_DATOS[[#This Row],[Hr. Actual]]=""),"",BASE_DATOS[[#This Row],[Hr. Actual]]-BASE_DATOS[[#This Row],[Hr.]]+BASE_DATOS[[#This Row],[Horas Acumuladas]]) | AJ11: =IFERROR(BASE_DATOS[[#This Row],[Precio US$]]/BASE_DATOS[[#This Row],[Horas Rodadas]],"") | AK11: =IFERROR(BASE_DATOS[[#This Row],[Horas Rodadas]]/(BASE_DATOS[[#This Row],[NSK Original]]-BASE_DATOS[[#This Row],[NSK]]),"") | AL11: =IF(BASE_DATOS[[#This Row],[Situación Actual]]="RETIRADO","",IF(BASE_DATOS[[#This Row],[Situación Actual]]="RODANDO",IFERROR(BASE_DATOS[[#This Row],[Hrs/mm]]*(BASE_DATOS[[#This Row],[NSK]]-BASE_DATOS[[#This Row],[NSK Form.]])+BASE_DATOS[[#This Row],[Horas Rodadas]],""))) | AM11: =IFERROR(BASE_DATOS[[#This Row],[Precio US$]]/BASE_DATOS[[#This Row],[Horas Proy.]],"") | AN11: =IF(OR(BASE_DATOS[[#This Row],[Km.]]="",BASE_DATOS[[#This Row],[Km. Actual]]=""),"",BASE_DATOS[[#This Row],[Km. Actual]]-BASE_DATOS[[#This Row],[Km.]]+BASE_DATOS[[#This Row],[Kilómetros Acumulados]]) | AO11: =IFERROR(BASE_DATOS[[#This Row],[Precio US$]]/BASE_DATOS[[#This Row],[Kilómetros Rodados]],"") | AP11: =IFERROR(BASE_DATOS[[#This Row],[Kilómetros Rodados]]/(BASE_DATOS[[#This Row],[NSK Original]]-BASE_DATOS[[#This Row],[NSK]]),"") | AQ11: =IF(BASE_DATOS[[#This Row],[Situación Actual]]="RETIRADO","",IF(BASE_DATOS[[#This Row],[Situación Actual]]="RODANDO",IFERROR(BASE_DATOS[[#This Row],[Kms/ mm]]*(BASE_DATOS[[#This Row],[NSK]]-BASE_DATOS[[#This Row],[NSK Form.]])+BASE_DATOS[[#This Row],[Kilómetros Rodados]],""))) | AR11: =IFERROR(BASE_DATOS[[#This Row],[Precio US$]]/BASE_DATOS[[#This Row],[Kilómetros Proy.]],"") | AS11: Rodando | AY11: =CONCATENATE(BASE_DATOS[[#This Row],[Código_U]]&BASE_DATOS[[#This Row],[Pos.]]&BASE_DATOS[[#This Row],[Situación Actual]]) -> TC-1006Rodando
A12: TC-100 | B12: F8U-901 | C12: Tracto | D12: Tracción | F12: Goodyear | G12: 295/80R22.5 | H12: =IF(BASE_DATOS[[#This Row],[N-R]]="N",BASE_DATOS[[#This Row],[Diseño]],"Reencauche") -> KMAXD | I12: KMAXD | J12: N | K12: 22.2 | L12: 110 | R12: 7 | S12: 45385 | V12: 21 | X12: 21 | Y12: =IFERROR(MIN(V12:X12),"") -> 21 | Z12: st | AA12: =IFERROR(BASE_DATOS[[#This Row],[NSK Original]]-BASE_DATOS[[#This Row],[NSK]]," ") -> 1.2 | AB12: ='NSK-TRACTO'!$A$2 -> 6 | AC12: =IF(BASE_DATOS[[#This Row],[NSK]]>=BASE_DATOS[[#This Row],[NSK Reen]],BASE_DATOS[[#This Row],[NSK Reen]],BASE_DATOS[[#This Row],[NSK]]) -> 6 | AD12: =IFERROR(100%-(BASE_DATOS[[#This Row],[NSK Reen]]/BASE_DATOS[[#This Row],[NSK Original]]),"") -> 0.72972973 | AE12: =IFERROR(100%-BASE_DATOS[[#This Row],[NSK]]/BASE_DATOS[[#This Row],[NSK Original]],"") -> 0.054054054 | AF12: =IFERROR(BASE_DATOS[[#This Row],[% Max Des.]]-BASE_DATOS[[#This Row],[% Des]],"") -> 0.67567568 | AI12: =IF(OR(BASE_DATOS[[#This Row],[Hr.]]="",BASE_DATOS[[#This Row],[Hr. Actual]]=""),"",BASE_DATOS[[#This Row],[Hr. Actual]]-BASE_DATOS[[#This Row],[Hr.]]+BASE_DATOS[[#This Row],[Horas Acumuladas]]) | AJ12: =IFERROR(BASE_DATOS[[#This Row],[Precio US$]]/BASE_DATOS[[#This Row],[Horas Rodadas]],"") | AK12: =IFERROR(BASE_DATOS[[#This Row],[Horas Rodadas]]/(BASE_DATOS[[#This Row],[NSK Original]]-BASE_DATOS[[#This Row],[NSK]]),"") | AL12: =IF(BASE_DATOS[[#This Row],[Situación Actual]]="RETIRADO","",IF(BASE_DATOS[[#This Row],[Situación Actual]]="RODANDO",IFERROR(BASE_DATOS[[#This Row],[Hrs/mm]]*(BASE_DATOS[[#This Row],[NSK]]-BASE_DATOS[[#This Row],[NSK Form.]])+BASE_DATOS[[#This Row],[Horas Rodadas]],""))) | AM12: =IFERROR(BASE_DATOS[[#This Row],[Precio US$]]/BASE_DATOS[[#This Row],[Horas Proy.]],"") | AN12: =IF(OR(BASE_DATOS[[#This Row],[Km.]]="",BASE_DATOS[[#This Row],[Km. Actual]]=""),"",BASE_DATOS[[#This Row],[Km. Actual]]-BASE_DATOS[[#This Row],[Km.]]+BASE_DATOS[[#This Row],[Kilómetros Acumulados]]) | AO12: =IFERROR(BASE_DATOS[[#This Row],[Precio US$]]/BASE_DATOS[[#This Row],[Kilómetros Rodados]],"") | AP12: =IFERROR(BASE_DATOS[[#This Row],[Kilómetros Rodados]]/(BASE_DATOS[[#This Row],[NSK Original]]-BASE_DATOS[[#This Row],[NSK]]),"") | AQ12: =IF(BASE_DATOS[[#This Row],[Situación Actual]]="RETIRADO","",IF(BASE_DATOS[[#This Row],[Situación Actual]]="RODANDO",IFERROR(BASE_DATOS[[#This Row],[Kms/ mm]]*(BASE_DATOS[[#This Row],[NSK]]-BASE_DATOS[[#This Row],[NSK Form.]])+BASE_DATOS[[#This Row],[Kilómetros Rodados]],""))) | AR12: =IFERROR(BASE_DATOS[[#This Row],[Precio US$]]/BASE_DATOS[[#This Row],[Kilómetros Proy.]],"") | AS12: Rodando | AY12: =CONCATENATE(BASE_DATOS[[#This Row],[Código_U]]&BASE_DATOS[[#This Row],[Pos.]]&BASE_DATOS[[#This Row],[Situación Actual]]) -> TC-1007Rodando
A13: TC-100 | B13: F8U-901 | C13: Tracto | D13: Tracción | F13: Goodyear | G13: 295/80R22.5 | H13: =IF(BASE_DATOS[[#This Row],[N-R]]="N",BASE_DATOS[[#This Row],[Diseño]],"Reencauche") -> KMAXD | I13: KMAXD | J13: N | K13: 22.2 | L13: 110 | R13: 8 | S13: 45385 | V13: 21 | X13: 21 | Y13: =IFERROR(MIN(V13:X13),"") -> 21 | Z13: tm | AA13: =IFERROR(BASE_DATOS[[#This Row],[NSK Original]]-BASE_DATOS[[#This Row],[NSK]]," ") -> 1.2 | AB13: ='NSK-TRACTO'!$A$2 -> 6 | AC13: =IF(BASE_DATOS[[#This Row],[NSK]]>=BASE_DATOS[[#This Row],[NSK Reen]],BASE_DATOS[[#This Row],[NSK Reen]],BASE_DATOS[[#This Row],[NSK]]) -> 6 | AD13: =IFERROR(100%-(BASE_DATOS[[#This Row],[NSK Reen]]/BASE_DATOS[[#This Row],[NSK Original]]),"") -> 0.72972973 | AE13: =IFERROR(100%-BASE_DATOS[[#This Row],[NSK]]/BASE_DATOS[[#This Row],[NSK Original]],"") -> 0.054054054 | AF13: =IFERROR(BASE_DATOS[[#This Row],[% Max Des.]]-BASE_DATOS[[#This Row],[% Des]],"") -> 0.67567568 | AI13: =IF(OR(BASE_DATOS[[#This Row],[Hr.]]="",BASE_DATOS[[#This Row],[Hr. Actual]]=""),"",BASE_DATOS[[#This Row],[Hr. Actual]]-BASE_DATOS[[#This Row],[Hr.]]+BASE_DATOS[[#This Row],[Horas Acumuladas]]) | AJ13: =IFERROR(BASE_DATOS[[#This Row],[Precio US$]]/BASE_DATOS[[#This Row],[Horas Rodadas]],"") | AK13: =IFERROR(BASE_DATOS[[#This Row],[Horas Rodadas]]/(BASE_DATOS[[#This Row],[NSK Original]]-BASE_DATOS[[#This Row],[NSK]]),"") | AL13: =IF(BASE_DATOS[[#This Row],[Situación Actual]]="RETIRADO","",IF(BASE_DATOS[[#This Row],[Situación Actual]]="RODANDO",IFERROR(BASE_DATOS[[#This Row],[Hrs/mm]]*(BASE_DATOS[[#This Row],[NSK]]-BASE_DATOS[[#This Row],[NSK Form.]])+BASE_DATOS[[#This Row],[Horas Rodadas]],""))) | AM13: =IFERROR(BASE_DATOS[[#This Row],[Precio US$]]/BASE_DATOS[[#This Row],[Horas Proy.]],"") | AN13: =IF(OR(BASE_DATOS[[#This Row],[Km.]]="",BASE_DATOS[[#This Row],[Km. Actual]]=""),"",BASE_DATOS[[#This Row],[Km. Actual]]-BASE_DATOS[[#This Row],[Km.]]+BASE_DATOS[[#This Row],[Kilómetros Acumulados]]) | AO13: =IFERROR(BASE_DATOS[[#This Row],[Precio US$]]/BASE_DATOS[[#This Row],[Kilómetros Rodados]],"") | AP13: =IFERROR(BASE_DATOS[[#This Row],[Kilómetros Rodados]]/(BASE_DATOS[[#This Row],[NSK Original]]-BASE_DATOS[[#This Row],[NSK]]),"") | AQ13: =IF(BASE_DATOS[[#This Row],[Situación Actual]]="RETIRADO","",IF(BASE_DATOS[[#This Row],[Situación Actual]]="RODANDO",IFERROR(BASE_DATOS[[#This Row],[Kms/ mm]]*(BASE_DATOS[[#This Row],[NSK]]-BASE_DATOS[[#This Row],[NSK Form.]])+BASE_DATOS[[#This Row],[Kilómetros Rodados]],""))) | AR13: =IFERROR(BASE_DATOS[[#This Row],[Precio US$]]/BASE_DATOS[[#This Row],[Kilómetros Proy.]],"") | AS13: Rodando | AY13: =CONCATENATE(BASE_DATOS[[#This Row],[Código_U]]&BASE_DATOS[[#This Row],[Pos.]]&BASE_DATOS[[#This Row],[Situación Actual]]) -> TC-1008Rodando
A14: TC-100 | B14: F8U-901 | C14: Tracto | D14: Tracción | F14: Goodyear | G14: 295/80R22.5 | H14: =IF(BASE_DATOS[[#This Row],[N-R]]="N",BASE_DATOS[[#This Row],[Diseño]],"Reencauche") -> KMAXD | I14: KMAXD | J14: N | K14: 22.2 | L14: 110 | R14: 9 | S14: 45385 | V14: 21 | X14: 21 | Y14: =IFERROR(MIN(V14:X14),"") -> 21 | Z14: st | AA14: =IFERROR(BASE_DATOS[[#This Row],[NSK Original]]-BASE_DATOS[[#This Row],[NSK]]," ") -> 1.2 | AB14: ='NSK-TRACTO'!$A$2 -> 6 | AC14: =IF(BASE_DATOS[[#This Row],[NSK]]>=BASE_DATOS[[#This Row],[NSK Reen]],BASE_DATOS[[#This Row],[NSK Reen]],BASE_DATOS[[#This Row],[NSK]]) -> 6 | AD14: =IFERROR(100%-(BASE_DATOS[[#This Row],[NSK Reen]]/BASE_DATOS[[#This Row],[NSK Original]]),"") -> 0.72972973 | AE14: =IFERROR(100%-BASE_DATOS[[#This Row],[NSK]]/BASE_DATOS[[#This Row],[NSK Original]],"") -> 0.054054054 | AF14: =IFERROR(BASE_DATOS[[#This Row],[% Max Des.]]-BASE_DATOS[[#This Row],[% Des]],"") -> 0.67567568 | AI14: =IF(OR(BASE_DATOS[[#This Row],[Hr.]]="",BASE_DATOS[[#This Row],[Hr. Actual]]=""),"",BASE_DATOS[[#This Row],[Hr. Actual]]-BASE_DATOS[[#This Row],[Hr.]]+BASE_DATOS[[#This Row],[Horas Acumuladas]]) | AJ14: =IFERROR(BASE_DATOS[[#This Row],[Precio US$]]/BASE_DATOS[[#This Row],[Horas Rodadas]],"") | AK14: =IFERROR(BASE_DATOS[[#This Row],[Horas Rodadas]]/(BASE_DATOS[[#This Row],[NSK Original]]-BASE_DATOS[[#This Row],[NSK]]),"") | AL14: =IF(BASE_DATOS[[#This Row],[Situación Actual]]="RETIRADO","",IF(BASE_DATOS[[#This Row],[Situación Actual]]="RODANDO",IFERROR(BASE_DATOS[[#This Row],[Hrs/mm]]*(BASE_DATOS[[#This Row],[NSK]]-BASE_DATOS[[#This Row],[NSK Form.]])+BASE_DATOS[[#This Row],[Horas Rodadas]],""))) | AM14: =IFERROR(BASE_DATOS[[#This Row],[Precio US$]]/BASE_DATOS[[#This Row],[Horas Proy.]],"") | AN14: =IF(OR(BASE_DATOS[[#This Row],[Km.]]="",BASE_DATOS[[#This Row],[Km. Actual]]=""),"",BASE_DATOS[[#This Row],[Km. Actual]]-BASE_DATOS[[#This Row],[Km.]]+BASE_DATOS[[#This Row],[Kilómetros Acumulados]]) | AO14: =IFERROR(BASE_DATOS[[#This Row],[Precio US$]]/BASE_DATOS[[#This Row],[Kilómetros Rodados]],"") | AP14: =IFERROR(BASE_DATOS[[#This Row],[Kilómetros Rodados]]/(BASE_DATOS[[#This Row],[NSK Original]]-BASE_DATOS[[#This Row],[NSK]]),"") | AQ14: =IF(BASE_DATOS[[#This Row],[Situación Actual]]="RETIRADO","",IF(BASE_DATOS[[#This Row],[Situación Actual]]="RODANDO",IFERROR(BASE_DATOS[[#This Row],[Kms/ mm]]*(BASE_DATOS[[#This Row],[NSK]]-BASE_DATOS[[#This Row],[NSK Form.]])+BASE_DATOS[[#This Row],[Kilómetros Rodados]],""))) | AR14: =IFERROR(BASE_DATOS[[#This Row],[Precio US$]]/BASE_DATOS[[#This Row],[Kilómetros Proy.]],"") | AS14: Rodando | AY14: =CONCATENATE(BASE_DATOS[[#This Row],[Código_U]]&BASE_DATOS[[#This Row],[Pos.]]&BASE_DATOS[[#This Row],[Situación Actual]]) -> TC-1009Rodando
A15: TC-100 | B15: F8U-901 | C15: Tracto | D15: Tracción | F15: Goodyear | G15: 295/80R22.5 | H15: =IF(BASE_DATOS[[#This Row],[N-R]]="N",BASE_DATOS[[#This Row],[Diseño]],"Reencauche") -> KMAXD | I15: KMAXD | J15: N | K15: 22.2 | L15: 110 | R15: 10 | S15: 45385 | V15: 21 | X15: 21 | Y15: =IFERROR(MIN(V15:X15),"") -> 21 | Z15: st | AA15: =IFERROR(BASE_DATOS[[#This Row],[NSK Original]]-BASE_DATOS[[#This Row],[NSK]]," ") -> 1.2 | AB15: ='NSK-TRACTO'!$A$2 -> 6 | AC15: =IF(BASE_DATOS[[#This Row],[NSK]]>=BASE_DATOS[[#This Row],[NSK Reen]],BASE_DATOS[[#This Row],[NSK Reen]],BASE_DATOS[[#This Row],[NSK]]) -> 6 | AD15: =IFERROR(100%-(BASE_DATOS[[#This Row],[NSK Reen]]/BASE_DATOS[[#This Row],[NSK Original]]),"") -> 0.72972973 | AE15: =IFERROR(100%-BASE_DATOS[[#This Row],[NSK]]/BASE_DATOS[[#This Row],[NSK Original]],"") -> 0.054054054 | AF15: =IFERROR(BASE_DATOS[[#This Row],[% Max Des.]]-BASE_DATOS[[#This Row],[% Des]],"") -> 0.67567568 | AI15: =IF(OR(BASE_DATOS[[#This Row],[Hr.]]="",BASE_DATOS[[#This Row],[Hr. Actual]]=""),"",BASE_DATOS[[#This Row],[Hr. Actual]]-BASE_DATOS[[#This Row],[Hr.]]+BASE_DATOS[[#This Row],[Horas Acumuladas]]) | AJ15: =IFERROR(BASE_DATOS[[#This Row],[Precio US$]]/BASE_DATOS[[#This Row],[Horas Rodadas]],"") | AK15: =IFERROR(BASE_DATOS[[#This Row],[Horas Rodadas]]/(BASE_DATOS[[#This Row],[NSK Original]]-BASE_DATOS[[#This Row],[NSK]]),"") | AL15: =IF(BASE_DATOS[[#This Row],[Situación Actual]]="RETIRADO","",IF(BASE_DATOS[[#This Row],[Situación Actual]]="RODANDO",IFERROR(BASE_DATOS[[#This Row],[Hrs/mm]]*(BASE_DATOS[[#This Row],[NSK]]-BASE_DATOS[[#This Row],[NSK Form.]])+BASE_DATOS[[#This Row],[Horas Rodadas]],""))) | AM15: =IFERROR(BASE_DATOS[[#This Row],[Precio US$]]/BASE_DATOS[[#This Row],[Horas Proy.]],"") | AN15: =IF(OR(BASE_DATOS[[#This Row],[Km.]]="",BASE_DATOS[[#This Row],[Km. Actual]]=""),"",BASE_DATOS[[#This Row],[Km. Actual]]-BASE_DATOS[[#This Row],[Km.]]+BASE_DATOS[[#This Row],[Kilómetros Acumulados]]) | AO15: =IFERROR(BASE_DATOS[[#This Row],[Precio US$]]/BASE_DATOS[[#This Row],[Kilómetros Rodados]],"") | AP15: =IFERROR(BASE_DATOS[[#This Row],[Kilómetros Rodados]]/(BASE_DATOS[[#This Row],[NSK Original]]-BASE_DATOS[[#This Row],[NSK]]),"") | AQ15: =IF(BASE_DATOS[[#This Row],[Situación Actual]]="RETIRADO","",IF(BASE_DATOS[[#This Row],[Situación Actual]]="RODANDO",IFERROR(BASE_DATOS[[#This Row],[Kms/ mm]]*(BASE_DATOS[[#This Row],[NSK]]-BASE_DATOS[[#This Row],[NSK Form.]])+BASE_DATOS[[#This Row],[Kilómetros Rodados]],""))) | AR15: =IFERROR(BASE_DATOS[[#This Row],[Precio US$]]/BASE_DATOS[[#This Row],[Kilómetros Proy.]],"") | AS15: Rodando | AY15: =CONCATENATE(BASE_DATOS[[#This Row],[Código_U]]&BASE_DATOS[[#This Row],[Pos.]]&BASE_DATOS[[#This Row],[Situación Actual]]) -> TC-10010Rodando
A16: SR-100 | B16: TOU-972 | C16: Encapsulado | D16: Libre | F16: Aeolus | G16: 445/65R22.5 | H16: =IF(BASE_DATOS[[#This Row],[N-R]]="N",BASE_DATOS[[#This Row],[Diseño]],"Reencauche") -> AGC28 | I16: AGC28 | J16: N | K16: 16.5 | L16: 110 | R16: 1 | S16: 45385 | V16: 8 | W16: 7 | X16: 8 | Y16: =IFERROR(MIN(V16:X16),"") -> 7 | Z16: st | AA16: =IFERROR(BASE_DATOS[[#This Row],[NSK Original]]-BASE_DATOS[[#This Row],[NSK]]," ") -> 9.5 | AB16: ='NSK-TRACTO'!$A$2 -> 6 | AC16: =IF(BASE_DATOS[[#This Row],[NSK]]>=BASE_DATOS[[#This Row],[NSK Reen]],BASE_DATOS[[#This Row],[NSK Reen]],BASE_DATOS[[#This Row],[NSK]]) -> 6 | AD16: =IFERROR(100%-(BASE_DATOS[[#This Row],[NSK Reen]]/BASE_DATOS[[#This Row],[NSK Original]]),"") -> 0.63636364 | AE16: =IFERROR(100%-BASE_DATOS[[#This Row],[NSK]]/BASE_DATOS[[#This Row],[NSK Original]],"") -> 0.57575758 | AF16: =IFERROR(BASE_DATOS[[#This Row],[% Max Des.]]-BASE_DATOS[[#This Row],[% Des]],"") -> 0.060606061 | AI16: =IF(OR(BASE_DATOS[[#This Row],[Hr.]]="",BASE_DATOS[[#This Row],[Hr. Actual]]=""),"",BASE_DATOS[[#This Row],[Hr. Actual]]-BASE_DATOS[[#This Row],[Hr.]]+BASE_DATOS[[#This Row],[Horas Acumuladas]]) | AJ16: =IFERROR(BASE_DATOS[[#This Row],[Precio US$]]/BASE_DATOS[[#This Row],[Horas Rodadas]],"") | AK16: =IFERROR(BASE_DATOS[[#This Row],[Horas Rodadas]]/(BASE_DATOS[[#This Row],[NSK Original]]-BASE_DATOS[[#This Row],[NSK]]),"") | AL16: =IF(BASE_DATOS[[#This Row],[Situación Actual]]="RETIRADO","",IF(BASE_DATOS[[#This Row],[Situación Actual]]="RODANDO",IFERROR(BASE_DATOS[[#This Row],[Hrs/mm]]*(BASE_DATOS[[#This Row],[NSK]]-BASE_DATOS[[#This Row],[NSK Form.]])+BASE_DATOS[[#This Row],[Horas Rodadas]],""))) | AM16: =IFERROR(BASE_DATOS[[#This Row],[Precio US$]]/BASE_DATOS[[#This Row],[Horas Proy.]],"") | AN16: =IF(OR(BASE_DATOS[[#This Row],[Km.]]="",BASE_DATOS[[#This Row],[Km. Actual]]=""),"",BASE_DATOS[[#This Row],[Km. Actual]]-BASE_DATOS[[#This Row],[Km.]]+BASE_DATOS[[#This Row],[Kilómetros Acumulados]]) | AO16: =IFERROR(BASE_DATOS[[#This Row],[Precio US$]]/BASE_DATOS[[#This Row],[Kilómetros Rodados]],"") | AP16: =IFERROR(BASE_DATOS[[#This Row],[Kilómetros Rodados]]/(BASE_DATOS[[#This Row],[NSK Original]]-BASE_DATOS[[#This Row],[NSK]]),"") | AQ16: =IF(BASE_DATOS[[#This Row],[Situación Actual]]="RETIRADO","",IF(BASE_DATOS[[#This Row],[Situación Actual]]="RODANDO",IFERROR(BASE_DATOS[[#This Row],[Kms/ mm]]*(BASE_DATOS[[#This Row],[NSK]]-BASE_DATOS[[#This Row],[NSK Form.]])+BASE_DATOS[[#This Row],[Kilómetros Rodados]],""))) | AR16: =IFERROR(BASE_DATOS[[#This Row],[Precio US$]]/BASE_DATOS[[#This Row],[Kilómetros Proy.]],"") | AS16: Rodando | AY16: =CONCATENATE(BASE_DATOS[[#This Row],[Código_U]]&BASE_DATOS[[#This Row],[Pos.]]&BASE_DATOS[[#This Row],[Situación Actual]]) -> SR-1001Rodando
A17: SR-100 | B17: TOU-972 | C17: Encapsulado | D17: Libre | E17: 100 6 | F17: Aeolus | G17: 445/65R22.5 | H17: =IF(BASE_DATOS[[#This Row],[N-R]]="N",BASE_DATOS[[#This Row],[Diseño]],"Reencauche") -> AGC28 | I17: AGC28 | J17: N | K17: 16.5 | L17: 110 | R17: 2 | S17: 45385 | V17: 8 | W17: 7 | X17: 8 | Y17: =IFERROR(MIN(V17:X17),"") -> 7 | Z17: tm | AA17: =IFERROR(BASE_DATOS[[#This Row],[NSK Original]]-BASE_DATOS[[#This Row],[NSK]]," ") -> 9.5 | AB17: ='NSK-TRACTO'!$A$2 -> 6 | AC17: =IF(BASE_DATOS[[#This Row],[NSK]]>=BASE_DATOS[[#This Row],[NSK Reen]],BASE_DATOS[[#This Row],[NSK Reen]],BASE_DATOS[[#This Row],[NSK]]) -> 6 | AD17: =IFERROR(100%-(BASE_DATOS[[#This Row],[NSK Reen]]/BASE_DATOS[[#This Row],[NSK Original]]),"") -> 0.63636364 | AE17: =IFERROR(100%-BASE_DATOS[[#This Row],[NSK]]/BASE_DATOS[[#This Row],[NSK Original]],"") -> 0.57575758 | AF17: =IFERROR(BASE_DATOS[[#This Row],[% Max Des.]]-BASE_DATOS[[#This Row],[% Des]],"") -> 0.060606061 | AI17: =IF(OR(BASE_DATOS[[#This Row],[Hr.]]="",BASE_DATOS[[#This Row],[Hr. Actual]]=""),"",BASE_DATOS[[#This Row],[Hr. Actual]]-BASE_DATOS[[#This Row],[Hr.]]+BASE_DATOS[[#This Row],[Horas Acumuladas]]) | AJ17: =IFERROR(BASE_DATOS[[#This Row],[Precio US$]]/BASE_DATOS[[#This Row],[Horas Rodadas]],"") | AK17: =IFERROR(BASE_DATOS[[#This Row],[Horas Rodadas]]/(BASE_DATOS[[#This Row],[NSK Original]]-BASE_DATOS[[#This Row],[NSK]]),"") | AL17: =IF(BASE_DATOS[[#This Row],[Situación Actual]]="RETIRADO","",IF(BASE_DATOS[[#This Row],[Situación Actual]]="RODANDO",IFERROR(BASE_DATOS[[#This Row],[Hrs/mm]]*(BASE_DATOS[[#This Row],[NSK]]-BASE_DATOS[[#This Row],[NSK Form.]])+BASE_DATOS[[#This Row],[Horas Rodadas]],""))) | AM17: =IFERROR(BASE_DATOS[[#This Row],[Precio US$]]/BASE_DATOS[[#This Row],[Horas Proy.]],"") | AN17: =IF(OR(BASE_DATOS[[#This Row],[Km.]]="",BASE_DATOS[[#This Row],[Km. Actual]]=""),"",BASE_DATOS[[#This Row],[Km. Actual]]-BASE_DATOS[[#This Row],[Km.]]+BASE_DATOS[[#This Row],[Kilómetros Acumulados]]) | AO17: =IFERROR(BASE_DATOS[[#This Row],[Precio US$]]/BASE_DATOS[[#This Row],[Kilómetros Rodados]],"") | AP17: =IFERROR(BASE_DATOS[[#This Row],[Kilómetros Rodados]]/(BASE_DATOS[[#This Row],[NSK Original]]-BASE_DATOS[[#This Row],[NSK]]),"") | AQ17: =IF(BASE_DATOS[[#This Row],[Situación Actual]]="RETIRADO","",IF(BASE_DATOS[[#This Row],[Situación Actual]]="RODANDO",IFERROR(BASE_DATOS[[#This Row],[Kms/ mm]]*(BASE_DATOS[[#This Row],[NSK]]-BASE_DATOS[[#This Row],[NSK Form.]])+BASE_DATOS[[#This Row],[Kilómetros Rodados]],""))) | AR17: =IFERROR(BASE_DATOS[[#This Row],[Precio US$]]/BASE_DATOS[[#This Row],[Kilómetros Proy.]],"") | AS17: Rodando | AY17: =CONCATENATE(BASE_DATOS[[#This Row],[Código_U]]&BASE_DATOS[[#This Row],[Pos.]]&BASE_DATOS[[#This Row],[Situación Actual]]) -> SR-1002Rodando
A18: SR-100 | B18: TOU-972 | C18: Encapsulado | D18: Libre | E18: 100 3 | F18: Aeolus | G18: 445/65R22.5 | H18: =IF(BASE_DATOS[[#This Row],[N-R]]="N",BASE_DATOS[[#This Row],[Diseño]],"Reencauche") -> AGC28 | I18: AGC28 | J18: N | K18: 16.5 | L18: 110 | R18: 3 | S18: 45385 | V18: 13 | W18: 13 | X18: 13 | Y18: =IFERROR(MIN(V18:X18),"") -> 13 | Z18: st | AA18: =IFERROR(BASE_DATOS[[#This Row],[NSK Original]]-BASE_DATOS[[#This Row],[NSK]]," ") -> 3.5 | AB18: ='NSK-TRACTO'!$A$2 -> 6 | AC18: =IF(BASE_DATOS[[#This Row],[NSK]]>=BASE_DATOS[[#This Row],[NSK Reen]],BASE_DATOS[[#This Row],[NSK Reen]],BASE_DATOS[[#This Row],[NSK]]) -> 6 | AD18: =IFERROR(100%-(BASE_DATOS[[#This Row],[NSK Reen]]/BASE_DATOS[[#This Row],[NSK Original]]),"") -> 0.63636364 | AE18: =IFERROR(100%-BASE_DATOS[[#This Row],[NSK]]/BASE_DATOS[[#This Row],[NSK Original]],"") -> 0.21212121 | AF18: =IFERROR(BASE_DATOS[[#This Row],[% Max Des.]]-BASE_DATOS[[#This Row],[% Des]],"") -> 0.42424242 | AI18: =IF(OR(BASE_DATOS[[#This Row],[Hr.]]="",BASE_DATOS[[#This Row],[Hr. Actual]]=""),"",BASE_DATOS[[#This Row],[Hr. Actual]]-BASE_DATOS[[#This Row],[Hr.]]+BASE_DATOS[[#This Row],[Horas Acumuladas]]) | AJ18: =IFERROR(BASE_DATOS[[#This Row],[Precio US$]]/BASE_DATOS[[#This Row],[Horas Rodadas]],"") | AK18: =IFERROR(BASE_DATOS[[#This Row],[Horas Rodadas]]/(BASE_DATOS[[#This Row],[NSK Original]]-BASE_DATOS[[#This Row],[NSK]]),"") | AL18: =IF(BASE_DATOS[[#This Row],[Situación Actual]]="RETIRADO","",IF(BASE_DATOS[[#This Row],[Situación Actual]]="RODANDO",IFERROR(BASE_DATOS[[#This Row],[Hrs/mm]]*(BASE_DATOS[[#This Row],[NSK]]-BASE_DATOS[[#This Row],[NSK Form.]])+BASE_DATOS[[#This Row],[Horas Rodadas]],""))) | AM18: =IFERROR(BASE_DATOS[[#This Row],[Precio US$]]/BASE_DATOS[[#This Row],[Horas Proy.]],"") | AN18: =IF(OR(BASE_DATOS[[#This Row],[Km.]]="",BASE_DATOS[[#This Row],[Km. Actual]]=""),"",BASE_DATOS[[#This Row],[Km. Actual]]-BASE_DATOS[[#This Row],[Km.]]+BASE_DATOS[[#This Row],[Kilómetros Acumulados]]) | AO18: =IFERROR(BASE_DATOS[[#This Row],[Precio US$]]/BASE_DATOS[[#This Row],[Kilómetros Rodados]],"") | AP18: =IFERROR(BASE_DATOS[[#This Row],[Kilómetros Rodados]]/(BASE_DATOS[[#This Row],[NSK Original]]-BASE_DATOS[[#This Row],[NSK]]),"") | AQ18: =IF(BASE_DATOS[[#This Row],[Situación Actual]]="RETIRADO","",IF(BASE_DATOS[[#This Row],[Situación Actual]]="RODANDO",IFERROR(BASE_DATOS[[#This Row],[Kms/ mm]]*(BASE_DATOS[[#This Row],[NSK]]-BASE_DATOS[[#This Row],[NSK Form.]])+BASE_DATOS[[#This Row],[Kilómetros Rodados]],""))) | AR18: =IFERROR(BASE_DATOS[[#This Row],[Precio US$]]/BASE_DATOS[[#This Row],[Kilómetros Proy.]],"") | AS18: Rodando | AY18: =CONCATENATE(BASE_DATOS[[#This Row],[Código_U]]&BASE_DATOS[[#This Row],[Pos.]]&BASE_DATOS[[#This Row],[Situación Actual]]) -> SR-1003Rodando
A19: SR-100 | B19: TOU-972 | C19: Encapsulado | D19: Libre | E19: 100 4 | F19: Aeolus | G19: 445/65R22.5 | H19: =IF(BASE_DATOS[[#This Row],[N-R]]="N",BASE_DATOS[[#This Row],[Diseño]],"Reencauche") -> AGC28 | I19: AGC28 | J19: N | K19: 16.5 | L19: 110 | R19: 4 | S19: 45385 | V19: 14 | W19: 14 | X19: 14 | Y19: =IFERROR(MIN(V19:X19),"") -> 14 | Z19: st | AA19: =IFERROR(BASE_DATOS[[#This Row],[NSK Original]]-BASE_DATOS[[#This Row],[NSK]]," ") -> 2.5 | AB19: ='NSK-TRACTO'!$A$2 -> 6 | AC19: =IF(BASE_DATOS[[#This Row],[NSK]]>=BASE_DATOS[[#This Row],[NSK Reen]],BASE_DATOS[[#This Row],[NSK Reen]],BASE_DATOS[[#This Row],[NSK]]) -> 6 | AD19: =IFERROR(100%-(BASE_DATOS[[#This Row],[NSK Reen]]/BASE_DATOS[[#This Row],[NSK Original]]),"") -> 0.63636364 | AE19: =IFERROR(100%-BASE_DATOS[[#This Row],[NSK]]/BASE_DATOS[[#This Row],[NSK Original]],"") -> 0.15151515 | AF19: =IFERROR(BASE_DATOS[[#This Row],[% Max Des.]]-BASE_DATOS[[#This Row],[% Des]],"") -> 0.48484848 | AI19: =IF(OR(BASE_DATOS[[#This Row],[Hr.]]="",BASE_DATOS[[#This Row],[Hr. Actual]]=""),"",BASE_DATOS[[#This Row],[Hr. Actual]]-BASE_DATOS[[#This Row],[Hr.]]+BASE_DATOS[[#This Row],[Horas Acumuladas]]) | AJ19: =IFERROR(BASE_DATOS[[#This Row],[Precio US$]]/BASE_DATOS[[#This Row],[Horas Rodadas]],"") | AK19: =IFERROR(BASE_DATOS[[#This Row],[Horas Rodadas]]/(BASE_DATOS[[#This Row],[NSK Original]]-BASE_DATOS[[#This Row],[NSK]]),"") | AL19: =IF(BASE_DATOS[[#This Row],[Situación Actual]]="RETIRADO","",IF(BASE_DATOS[[#This Row],[Situación Actual]]="RODANDO",IFERROR(BASE_DATOS[[#This Row],[Hrs/mm]]*(BASE_DATOS[[#This Row],[NSK]]-BASE_DATOS[[#This Row],[NSK Form.]])+BASE_DATOS[[#This Row],[Horas Rodadas]],""))) | AM19: =IFERROR(BASE_DATOS[[#This Row],[Precio US$]]/BASE_DATOS[[#This Row],[Horas Proy.]],"") | AN19: =IF(OR(BASE_DATOS[[#This Row],[Km.]]="",BASE_DATOS[[#This Row],[Km. Actual]]=""),"",BASE_DATOS[[#This Row],[Km. Actual]]-BASE_DATOS[[#This Row],[Km.]]+BASE_DATOS[[#This Row],[Kilómetros Acumulados]]) | AO19: =IFERROR(BASE_DATOS[[#This Row],[Precio US$]]/BASE_DATOS[[#This Row],[Kilómetros Rodados]],"") | AP19: =IFERROR(BASE_DATOS[[#This Row],[Kilómetros Rodados]]/(BASE_DATOS[[#This Row],[NSK Original]]-BASE_DATOS[[#This Row],[NSK]]),"") | AQ19: =IF(BASE_DATOS[[#This Row],[Situación Actual]]="RETIRADO","",IF(BASE_DATOS[[#This Row],[Situación Actual]]="RODANDO",IFERROR(BASE_DATOS[[#This Row],[Kms/ mm]]*(BASE_DATOS[[#This Row],[NSK]]-BASE_DATOS[[#This Row],[NSK Form.]])+BASE_DATOS[[#This Row],[Kilómetros Rodados]],""))) | AR19: =IFERROR(BASE_DATOS[[#This Row],[Precio US$]]/BASE_DATOS[[#This Row],[Kilómetros Proy.]],"") | AS19: Rodando | AY19: =CONCATENATE(BASE_DATOS[[#This Row],[Código_U]]&BASE_DATOS[[#This Row],[Pos.]]&BASE_DATOS[[#This Row],[Situación Actual]]) -> SR-1004Rodando
A20: SR-100 | B20: TOU-972 | C20: Encapsulado | D20: Libre | E20: 100 | F20: Aeolus | G20: 445/65R22.5 | H20: =IF(BASE_DATOS[[#This Row],[N-R]]="N",BASE_DATOS[[#This Row],[Diseño]],"Reencauche") -> AGC28 | I20: AGC28 | J20: N | K20: 16.5 | L20: 110 | R20: 5 | S20: 45385 | V20: 13 | W20: 13 | X20: 13 | Y20: =IFERROR(MIN(V20:X20),"") -> 13 | Z20: st | AA20: =IFERROR(BASE_DATOS[[#This Row],[NSK Original]]-BASE_DATOS[[#This Row],[NSK]]," ") -> 3.5 | AB20: ='NSK-TRACTO'!$A$2 -> 6 | AC20: =IF(BASE_DATOS[[#This Row],[NSK]]>=BASE_DATOS[[#This Row],[NSK Reen]],BASE_DATOS[[#This Row],[NSK Reen]],BASE_DATOS[[#This Row],[NSK]]) -> 6 | AD20: =IFERROR(100%-(BASE_DATOS[[#This Row],[NSK Reen]]/BASE_DATOS[[#This Row],[NSK Original]]),"") -> 0.63636364 | AE20: =IFERROR(100%-BASE_DATOS[[#This Row],[NSK]]/BASE_DATOS[[#This Row],[NSK Original]],"") -> 0.21212121 | AF20: =IFERROR(BASE_DATOS[[#This Row],[% Max Des.]]-BASE_DATOS[[#This Row],[% Des]],"") -> 0.42424242 | AI20: =IF(OR(BASE_DATOS[[#This Row],[Hr.]]="",BASE_DATOS[[#This Row],[Hr. Actual]]=""),"",BASE_DATOS[[#This Row],[Hr. Actual]]-BASE_DATOS[[#This Row],[Hr.]]+BASE_DATOS[[#This Row],[Horas Acumuladas]]) | AJ20: =IFERROR(BASE_DATOS[[#This Row],[Precio US$]]/BASE_DATOS[[#This Row],[Horas Rodadas]],"") | AK20: =IFERROR(BASE_DATOS[[#This Row],[Horas Rodadas]]/(BASE_DATOS[[#This Row],[NSK Original]]-BASE_DATOS[[#This Row],[NSK]]),"") | AL20: =IF(BASE_DATOS[[#This Row],[Situación Actual]]="RETIRADO","",IF(BASE_DATOS[[#This Row],[Situación Actual]]="RODANDO",IFERROR(BASE_DATOS[[#This Row],[Hrs/mm]]*(BASE_DATOS[[#This Row],[NSK]]-BASE_DATOS[[#This Row],[NSK Form.]])+BASE_DATOS[[#This Row],[Horas Rodadas]],""))) | AM20: =IFERROR(BASE_DATOS[[#This Row],[Precio US$]]/BASE_DATOS[[#This Row],[Horas Proy.]],"") | AN20: =IF(OR(BASE_DATOS[[#This Row],[Km.]]="",BASE_DATOS[[#This Row],[Km. Actual]]=""),"",BASE_DATOS[[#This Row],[Km. Actual]]-BASE_DATOS[[#This Row],[Km.]]+BASE_DATOS[[#This Row],[Kilómetros Acumulados]]) | AO20: =IFERROR(BASE_DATOS[[#This Row],[Precio US$]]/BASE_DATOS[[#This Row],[Kilómetros Rodados]],"") | AP20: =IFERROR(BASE_DATOS[[#This Row],[Kilómetros Rodados]]/(BASE_DATOS[[#This Row],[NSK Original]]-BASE_DATOS[[#This Row],[NSK]]),"") | AQ20: =IF(BASE_DATOS[[#This Row],[Situación Actual]]="RETIRADO","",IF(BASE_DATOS[[#This Row],[Situación Actual]]="RODANDO",IFERROR(BASE_DATOS[[#This Row],[Kms/ mm]]*(BASE_DATOS[[#This Row],[NSK]]-BASE_DATOS[[#This Row],[NSK Form.]])+BASE_DATOS[[#This Row],[Kilómetros Rodados]],""))) | AR20: =IFERROR(BASE_DATOS[[#This Row],[Precio US$]]/BASE_DATOS[[#This Row],[Kilómetros Proy.]],"") | AS20: Rodando | AY20: =CONCATENATE(BASE_DATOS[[#This Row],[Código_U]]&BASE_DATOS[[#This Row],[Pos.]]&BASE_DATOS[[#This Row],[Situación Actual]]) -> SR-1005Rodando
A21: SR-100 | B21: TOU-972 | C21: Encapsulado | D21: Libre | E21: 100 | F21: Aeolus | G21: 445/65R22.5 | H21: =IF(BASE_DATOS[[#This Row],[N-R]]="N",BASE_DATOS[[#This Row],[Diseño]],"Reencauche") -> AGC28 | I21: AGC28 | J21: N | K21: 16.5 | L21: 110 | R21: 6 | S21: 45385 | V21: 10 | W21: 10 | X21: 11 | Y21: =IFERROR(MIN(V21:X21),"") -> 10 | Z21: st | AA21: =IFERROR(BASE_DATOS[[#This Row],[NSK Original]]-BASE_DATOS[[#This Row],[NSK]]," ") -> 6.5 | AB21: ='NSK-TRACTO'!$A$2 -> 6 | AC21: =IF(BASE_DATOS[[#This Row],[NSK]]>=BASE_DATOS[[#This Row],[NSK Reen]],BASE_DATOS[[#This Row],[NSK Reen]],BASE_DATOS[[#This Row],[NSK]]) -> 6 | AD21: =IFERROR(100%-(BASE_DATOS[[#This Row],[NSK Reen]]/BASE_DATOS[[#This Row],[NSK Original]]),"") -> 0.63636364 | AE21: =IFERROR(100%-BASE_DATOS[[#This Row],[NSK]]/BASE_DATOS[[#This Row],[NSK Original]],"") -> 0.39393939 | AF21: =IFERROR(BASE_DATOS[[#This Row],[% Max Des.]]-BASE_DATOS[[#This Row],[% Des]],"") -> 0.24242424 | AI21: =IF(OR(BASE_DATOS[[#This Row],[Hr.]]="",BASE_DATOS[[#This Row],[Hr. Actual]]=""),"",BASE_DATOS[[#This Row],[Hr. Actual]]-BASE_DATOS[[#This Row],[Hr.]]+BASE_DATOS[[#This Row],[Horas Acumuladas]]) | AJ21: =IFERROR(BASE_DATOS[[#This Row],[Precio US$]]/BASE_DATOS[[#This Row],[Horas Rodadas]],"") | AK21: =IFERROR(BASE_DATOS[[#This Row],[Horas Rodadas]]/(BASE_DATOS[[#This Row],[NSK Original]]-BASE_DATOS[[#This Row],[NSK]]),"") | AL21: =IF(BASE_DATOS[[#This Row],[Situación Actual]]="RETIRADO","",IF(BASE_DATOS[[#This Row],[Situación Actual]]="RODANDO",IFERROR(BASE_DATOS[[#This Row],[Hrs/mm]]*(BASE_DATOS[[#This Row],[NSK]]-BASE_DATOS[[#This Row],[NSK Form.]])+BASE_DATOS[[#This Row],[Horas Rodadas]],""))) | AM21: =IFERROR(BASE_DATOS[[#This Row],[Precio US$]]/BASE_DATOS[[#This Row],[Horas Proy.]],"") | AN21: =IF(OR(BASE_DATOS[[#This Row],[Km.]]="",BASE_DATOS[[#This Row],[Km. Actual]]=""),"",BASE_DATOS[[#This Row],[Km. Actual]]-BASE_DATOS[[#This Row],[Km.]]+BASE_DATOS[[#This Row],[Kilómetros Acumulados]]) | AO21: =IFERROR(BASE_DATOS[[#This Row],[Precio US$]]/BASE_DATOS[[#This Row],[Kilómetros Rodados]],"") | AP21: =IFERROR(BASE_DATOS[[#This Row],[Kilómetros Rodados]]/(BASE_DATOS[[#This Row],[NSK Original]]-BASE_DATOS[[#This Row],[NSK]]),"") | AQ21: =IF(BASE_DATOS[[#This Row],[Situación Actual]]="RETIRADO","",IF(BASE_DATOS[[#This Row],[Situación Actual]]="RODANDO",IFERROR(BASE_DATOS[[#This Row],[Kms/ mm]]*(BASE_DATOS[[#This Row],[NSK]]-BASE_DATOS[[#This Row],[NSK Form.]])+BASE_DATOS[[#This Row],[Kilómetros Rodados]],""))) | AR21: =IFERROR(BASE_DATOS[[#This Row],[Precio US$]]/BASE_DATOS[[#This Row],[Kilómetros Proy.]],"") | AS21: Rodando | AY21: =CONCATENATE(BASE_DATOS[[#This Row],[Código_U]]&BASE_DATOS[[#This Row],[Pos.]]&BASE_DATOS[[#This Row],[Situación Actual]]) -> SR-1006Rodando
A22: SR-100 | B22: TOU-972 | C22: Encapsulado | D22: RC | F22: Michelin | G22: 425/65R22.5 | H22: =IF(BASE_DATOS[[#This Row],[N-R]]="N",BASE_DATOS[[#This Row],[Diseño]],"Reencauche") -> Reencauche | I22: LZY3 | J22: 1R | K22: 19 | L22: 110 | R22: RE | S22: 45385 | V22: 8 | W22: 7 | X22: 8 | Y22: =IFERROR(MIN(V22:X22),"") -> 7 | Z22: st | AA22: =IFERROR(BASE_DATOS[[#This Row],[NSK Original]]-BASE_DATOS[[#This Row],[NSK]]," ") -> 12 | AB22: ='NSK-TRACTO'!$A$2 -> 6 | AC22: =IF(BASE_DATOS[[#This Row],[NSK]]>=BASE_DATOS[[#This Row],[NSK Reen]],BASE_DATOS[[#This Row],[NSK Reen]],BASE_DATOS[[#This Row],[NSK]]) -> 6 | AD22: =IFERROR(100%-(BASE_DATOS[[#This Row],[NSK Reen]]/BASE_DATOS[[#This Row],[NSK Original]]),"") -> 0.68421053 | AE22: =IFERROR(100%-BASE_DATOS[[#This Row],[NSK]]/BASE_DATOS[[#This Row],[NSK Original]],"") -> 0.63157895 | AF22: =IFERROR(BASE_DATOS[[#This Row],[% Max Des.]]-BASE_DATOS[[#This Row],[% Des]],"") -> 0.052631579 | AI22: =IF(OR(BASE_DATOS[[#This Row],[Hr.]]="",BASE_DATOS[[#This Row],[Hr. Actual]]=""),"",BASE_DATOS[[#This Row],[Hr. Actual]]-BASE_DATOS[[#This Row],[Hr.]]+BASE_DATOS[[#This Row],[Horas Acumuladas]]) | AJ22: =IFERROR(BASE_DATOS[[#This Row],[Precio US$]]/BASE_DATOS[[#This Row],[Horas Rodadas]],"") | AK22: =IFERROR(BASE_DATOS[[#This Row],[Horas Rodadas]]/(BASE_DATOS[[#This Row],[NSK Original]]-BASE_DATOS[[#This Row],[NSK]]),"") | AL22: =IF(BASE_DATOS[[#This Row],[Situación Actual]]="RETIRADO","",IF(BASE_DATOS[[#This Row],[Situación Actual]]="RODANDO",IFERROR(BASE_DATOS[[#This Row],[Hrs/mm]]*(BASE_DATOS[[#This Row],[NSK]]-BASE_DATOS[[#This Row],[NSK Form.]])+BASE_DATOS[[#This Row],[Horas Rodadas]],""))) | AM22: =IFERROR(BASE_DATOS[[#This Row],[Precio US$]]/BASE_DATOS[[#This Row],[Horas Proy.]],"") | AN22: =IF(OR(BASE_DATOS[[#This Row],[Km.]]="",BASE_DATOS[[#This Row],[Km. Actual]]=""),"",BASE_DATOS[[#This Row],[Km. Actual]]-BASE_DATOS[[#This Row],[Km.]]+BASE_DATOS[[#This Row],[Kilómetros Acumulados]]) | AO22: =IFERROR(BASE_DATOS[[#This Row],[Precio US$]]/BASE_DATOS[[#This Row],[Kilómetros Rodados]],"") | AP22: =IFERROR(BASE_DATOS[[#This Row],[Kilómetros Rodados]]/(BASE_DATOS[[#This Row],[NSK Original]]-BASE_DATOS[[#This Row],[NSK]]),"") | AQ22: =IF(BASE_DATOS[[#This Row],[Situación Actual]]="RETIRADO","",IF(BASE_DATOS[[#This Row],[Situación Actual]]="RODANDO",IFERROR(BASE_DATOS[[#This Row],[Kms/ mm]]*(BASE_DATOS[[#This Row],[NSK]]-BASE_DATOS[[#This Row],[NSK Form.]])+BASE_DATOS[[#This Row],[Kilómetros Rodados]],""))) | AR22: =IFERROR(BASE_DATOS[[#This Row],[Precio US$]]/BASE_DATOS[[#This Row],[Kilómetros Proy.]],"") | AS22: Rodando | AY22: =CONCATENATE(BASE_DATOS[[#This Row],[Código_U]]&BASE_DATOS[[#This Row],[Pos.]]&BASE_DATOS[[#This Row],[Situación Actual]]) -> SR-100RERodando
A23: SR-100 | B23: TOU-972 | C23: Encapsulado | D23: RT | F23: Continental | G23: 295/80R22.5 | H23: =IF(BASE_DATOS[[#This Row],[N-R]]="N",BASE_DATOS[[#This Row],[Diseño]],"Reencauche") -> HD3 | I23: HD3 | J23: N | K23: 0 | L23: 110 | R23: RT | S23: 45385 | V23: 10 | W23: 7 | X23: 10 | Y23: =IFERROR(MIN(V23:X23),"") -> 7 | Z23: st | AA23: =IFERROR(BASE_DATOS[[#This Row],[NSK Original]]-BASE_DATOS[[#This Row],[NSK]]," ") -> -7 | AB23: ='NSK-TRACTO'!$A$2 -> 6 | AC23: =IF(BASE_DATOS[[#This Row],[NSK]]>=BASE_DATOS[[#This Row],[NSK Reen]],BASE_DATOS[[#This Row],[NSK Reen]],BASE_DATOS[[#This Row],[NSK]]) -> 6 | AD23: =IFERROR(100%-(BASE_DATOS[[#This Row],[NSK Reen]]/BASE_DATOS[[#This Row],[NSK Original]]),"") | AE23: =IFERROR(100%-BASE_DATOS[[#This Row],[NSK]]/BASE_DATOS[[#This Row],[NSK Original]],"") | AF23: =IFERROR(BASE_DATOS[[#This Row],[% Max Des.]]-BASE_DATOS[[#This Row],[% Des]],"") | AI23: =IF(OR(BASE_DATOS[[#This Row],[Hr.]]="",BASE_DATOS[[#This Row],[Hr. Actual]]=""),"",BASE_DATOS[[#This Row],[Hr. Actual]]-BASE_DATOS[[#This Row],[Hr.]]+BASE_DATOS[[#This Row],[Horas Acumuladas]]) | AJ23: =IFERROR(BASE_DATOS[[#This Row],[Precio US$]]/BASE_DATOS[[#This Row],[Horas Rodadas]],"") | AK23: =IFERROR(BASE_DATOS[[#This Row],[Horas Rodadas]]/(BASE_DATOS[[#This Row],[NSK Original]]-BASE_DATOS[[#This Row],[NSK]]),"") | AL23: =IF(BASE_DATOS[[#This Row],[Situación Actual]]="RETIRADO","",IF(BASE_DATOS[[#This Row],[Situación Actual]]="RODANDO",IFERROR(BASE_DATOS[[#This Row],[Hrs/mm]]*(BASE_DATOS[[#This Row],[NSK]]-BASE_DATOS[[#This Row],[NSK Form.]])+BASE_DATOS[[#This Row],[Horas Rodadas]],""))) | AM23: =IFERROR(BASE_DATOS[[#This Row],[Precio US$]]/BASE_DATOS[[#This Row],[Horas Proy.]],"") | AN23: =IF(OR(BASE_DATOS[[#This Row],[Km.]]="",BASE_DATOS[[#This Row],[Km. Actual]]=""),"",BASE_DATOS[[#This Row],[Km. Actual]]-BASE_DATOS[[#This Row],[Km.]]+BASE_DATOS[[#This Row],[Kilómetros Acumulados]]) | AO23: =IFERROR(BASE_DATOS[[#This Row],[Precio US$]]/BASE_DATOS[[#This Row],[Kilómetros Rodados]],"") | AP23: =IFERROR(BASE_DATOS[[#This Row],[Kilómetros Rodados]]/(BASE_DATOS[[#This Row],[NSK Original]]-BASE_DATOS[[#This Row],[NSK]]),"") | AQ23: =IF(BASE_DATOS[[#This Row],[Situación Actual]]="RETIRADO","",IF(BASE_DATOS[[#This Row],[Situación Actual]]="RODANDO",IFERROR(BASE_DATOS[[#This Row],[Kms/ mm]]*(BASE_DATOS[[#This Row],[NSK]]-BASE_DATOS[[#This Row],[NSK Form.]])+BASE_DATOS[[#This Row],[Kilómetros Rodados]],""))) | AR23: =IFERROR(BASE_DATOS[[#This Row],[Precio US$]]/BASE_DATOS[[#This Row],[Kilómetros Proy.]],"") | AS23: Rodando | AY23: =CONCATENATE(BASE_DATOS[[#This Row],[Código_U]]&BASE_DATOS[[#This Row],[Pos.]]&BASE_DATOS[[#This Row],[Situación Actual]]) -> SR-100RTRodando
A24: TC-102 | B24: F8U-787 | C24: Tracto | D24: Direccional | E24: 102 1 | F24: Michelin | G24: 295/80R22.5 | H24: =IF(BASE_DATOS[[#This Row],[N-R]]="N",BASE_DATOS[[#This Row],[Diseño]],"Reencauche") -> XMULTI+Z | I24: XMULTI+Z | J24: N | K24: 16 | L24: 100 | R24: 1 | S24: 45385 | V24: 14 | W24: 14 | X24: 14 | Y24: =IFERROR(MIN(V24:X24),"") -> 14 | Z24: st | AA24: =IFERROR(BASE_DATOS[[#This Row],[NSK Original]]-BASE_DATOS[[#This Row],[NSK]]," ") -> 2 | AB24: ='NSK-TRACTO'!$A$2 -> 6 | AC24: =IF(BASE_DATOS[[#This Row],[NSK]]>=BASE_DATOS[[#This Row],[NSK Reen]],BASE_DATOS[[#This Row],[NSK Reen]],BASE_DATOS[[#This Row],[NSK]]) -> 6 | AD24: =IFERROR(100%-(BASE_DATOS[[#This Row],[NSK Reen]]/BASE_DATOS[[#This Row],[NSK Original]]),"") -> 0.625 | AE24: =IFERROR(100%-BASE_DATOS[[#This Row],[NSK]]/BASE_DATOS[[#This Row],[NSK Original]],"") -> 0.125 | AF24: =IFERROR(BASE_DATOS[[#This Row],[% Max Des.]]-BASE_DATOS[[#This Row],[% Des]],"") -> 0.5 | AI24: =IF(OR(BASE_DATOS[[#This Row],[Hr.]]="",BASE_DATOS[[#This Row],[Hr. Actual]]=""),"",BASE_DATOS[[#This Row],[Hr. Actual]]-BASE_DATOS[[#This Row],[Hr.]]+BASE_DATOS[[#This Row],[Horas Acumuladas]]) | AJ24: =IFERROR(BASE_DATOS[[#This Row],[Precio US$]]/BASE_DATOS[[#This Row],[Horas Rodadas]],"") | AK24: =IFERROR(BASE_DATOS[[#This Row],[Horas Rodadas]]/(BASE_DATOS[[#This Row],[NSK Original]]-BASE_DATOS[[#This Row],[NSK]]),"") | AL24: =IF(BASE_DATOS[[#This Row],[Situación Actual]]="RETIRADO","",IF(BASE_DATOS[[#This Row],[Situación Actual]]="RODANDO",IFERROR(BASE_DATOS[[#This Row],[Hrs/mm]]*(BASE_DATOS[[#This Row],[NSK]]-BASE_DATOS[[#This Row],[NSK Form.]])+BASE_DATOS[[#This Row],[Horas Rodadas]],""))) | AM24: =IFERROR(BASE_DATOS[[#This Row],[Precio US$]]/BASE_DATOS[[#This Row],[Horas Proy.]],"") | AN24: =IF(OR(BASE_DATOS[[#This Row],[Km.]]="",BASE_DATOS[[#This Row],[Km. Actual]]=""),"",BASE_DATOS[[#This Row],[Km. Actual]]-BASE_DATOS[[#This Row],[Km.]]+BASE_DATOS[[#This Row],[Kilómetros Acumulados]]) | AO24: =IFERROR(BASE_DATOS[[#This Row],[Precio US$]]/BASE_DATOS[[#This Row],[Kilómetros Rodados]],"") | AP24: =IFERROR(BASE_DATOS[[#This Row],[Kilómetros Rodados]]/(BASE_DATOS[[#This Row],[NSK Original]]-BASE_DATOS[[#This Row],[NSK]]),"") | AQ24: =IF(BASE_DATOS[[#This Row],[Situación Actual]]="RETIRADO","",IF(BASE_DATOS[[#This Row],[Situación Actual]]="RODANDO",IFERROR(BASE_DATOS[[#This Row],[Kms/ mm]]*(BASE_DATOS[[#This Row],[NSK]]-BASE_DATOS[[#This Row],[NSK Form.]])+BASE_DATOS[[#This Row],[Kilómetros Rodados]],""))) | AR24: =IFERROR(BASE_DATOS[[#This Row],[Precio US$]]/BASE_DATOS[[#This Row],[Kilómetros Proy.]],"") | AS24: Rodando | AY24: =CONCATENATE(BASE_DATOS[[#This Row],[Código_U]]&BASE_DATOS[[#This Row],[Pos.]]&BASE_DATOS[[#This Row],[Situación Actual]]) -> TC-1021Rodando
A25: TC-102 | B25: F8U-787 | C25: Tracto | D25: Direccional | E25: 102 2 | F25: Michelin | G25: 295/80R22.5 | H25: =IF(BASE_DATOS[[#This Row],[N-R]]="N",BASE_DATOS[[#This Row],[Diseño]],"Reencauche") -> XMULTI+Z | I25: XMULTI+Z | J25: N | K25: 16 | L25: 100 | R25: 2 | S25: 45385 | V25: 13 | W25: 13 | X25: 13 | Y25: =IFERROR(MIN(V25:X25),"") -> 13 | Z25: st | AA25: =IFERROR(BASE_DATOS[[#This Row],[NSK Original]]-BASE_DATOS[[#This Row],[NSK]]," ") -> 3 | AB25: ='NSK-TRACTO'!$A$2 -> 6 | AC25: =IF(BASE_DATOS[[#This Row],[NSK]]>=BASE_DATOS[[#This Row],[NSK Reen]],BASE_DATOS[[#This Row],[NSK Reen]],BASE_DATOS[[#This Row],[NSK]]) -> 6 | AD25: =IFERROR(100%-(BASE_DATOS[[#This Row],[NSK Reen]]/BASE_DATOS[[#This Row],[NSK Original]]),"") -> 0.625 | AE25: =IFERROR(100%-BASE_DATOS[[#This Row],[NSK]]/BASE_DATOS[[#This Row],[NSK Original]],"") -> 0.1875 | AF25: =IFERROR(BASE_DATOS[[#This Row],[% Max Des.]]-BASE_DATOS[[#This Row],[% Des]],"") -> 0.4375 | AI25: =IF(OR(BASE_DATOS[[#This Row],[Hr.]]="",BASE_DATOS[[#This Row],[Hr. Actual]]=""),"",BASE_DATOS[[#This Row],[Hr. Actual]]-BASE_DATOS[[#This Row],[Hr.]]+BASE_DATOS[[#This Row],[Horas Acumuladas]]) | AJ25: =IFERROR(BASE_DATOS[[#This Row],[Precio US$]]/BASE_DATOS[[#This Row],[Horas Rodadas]],"") | AK25: =IFERROR(BASE_DATOS[[#This Row],[Horas Rodadas]]/(BASE_DATOS[[#This Row],[NSK Original]]-BASE_DATOS[[#This Row],[NSK]]),"") | AL25: =IF(BASE_DATOS[[#This Row],[Situación Actual]]="RETIRADO","",IF(BASE_DATOS[[#This Row],[Situación Actual]]="RODANDO",IFERROR(BASE_DATOS[[#This Row],[Hrs/mm]]*(BASE_DATOS[[#This Row],[NSK]]-BASE_DATOS[[#This Row],[NSK Form.]])+BASE_DATOS[[#This Row],[Horas Rodadas]],""))) | AM25: =IFERROR(BASE_DATOS[[#This Row],[Precio US$]]/BASE_DATOS[[#This Row],[Horas Proy.]],"") | AN25: =IF(OR(BASE_DATOS[[#This Row],[Km.]]="",BASE_DATOS[[#This Row],[Km. Actual]]=""),"",BASE_DATOS[[#This Row],[Km. Actual]]-BASE_DATOS[[#This Row],[Km.]]+BASE_DATOS[[#This Row],[Kilómetros Acumulados]]) | AO25: =IFERROR(BASE_DATOS[[#This Row],[Precio US$]]/BASE_DATOS[[#This Row],[Kilómetros Rodados]],"") | AP25: =IFERROR(BASE_DATOS[[#This Row],[Kilómetros Rodados]]/(BASE_DATOS[[#This Row],[NSK Original]]-BASE_DATOS[[#This Row],[NSK]]),"") | AQ25: =IF(BASE_DATOS[[#This Row],[Situación Actual]]="RETIRADO","",IF(BASE_DATOS[[#This Row],[Situación Actual]]="RODANDO",IFERROR(BASE_DATOS[[#This Row],[Kms/ mm]]*(BASE_DATOS[[#This Row],[NSK]]-BASE_DATOS[[#This Row],[NSK Form.]])+BASE_DATOS[[#This Row],[Kilómetros Rodados]],""))) | AR25: =IFERROR(BASE_DATOS[[#This Row],[Precio US$]]/BASE_DATOS[[#This Row],[Kilómetros Proy.]],"") | AS25: Rodando | AY25: =CONCATENATE(BASE_DATOS[[#This Row],[Código_U]]&BASE_DATOS[[#This Row],[Pos.]]&BASE_DATOS[[#This Row],[Situación Actual]]) -> TC-1022Rodando
